<mujoco model="zero_with_robotiq_reach">
    <compiler angle="radian" meshdir="." />

    <option gravity="0 0 0" cone="elliptic" timestep="0.02" />
    <size njmax="600" nconmax="200" />

    <visual>
        <map znear="0.001" />
    </visual>

    <default>
        <joint damping="1" frictionloss="1" />
        <camera fovy="60" />
        <motor gear="1.0" />
        <geom contype="0" conaffinity="0" />
    </default>

    <asset>
        <mesh name="base_link_mesh" file="meshes/base_link.STL" />
        <mesh name="link1_mesh" file="meshes/link1.STL" />
        <mesh name="link2_mesh" file="meshes/link2.STL" />
        <mesh name="link3_mesh" file="meshes/link3.STL" />
        <mesh name="link4_mesh" file="meshes/link4.STL" />
        <mesh name="link5_mesh" file="meshes/link5.STL" />
        <mesh name="ee_link_mesh" file="meshes/ee_link.STL" />

        <mesh name="kinova_robotiq_coupler" file="meshes/robotiq/kinova_robotiq_coupler.stl" />
        <mesh name="robotiq_85_base_link" file="meshes/robotiq/robotiq_85_base_link.stl" />
        <mesh name="robotiq_85_finger_link" file="meshes/robotiq/robotiq_85_finger_link.stl" />
        <mesh name="robotiq_85_finger_tip_link" file="meshes/robotiq/robotiq_85_finger_tip_link.stl" />
        <mesh name="robotiq_85_inner_knuckle_link" file="meshes/robotiq/robotiq_85_inner_knuckle_link.stl" />
        <mesh name="robotiq_85_knuckle_link" file="meshes/robotiq/robotiq_85_knuckle_link.stl" />

        <material name="ArmMat" rgba="0.75 0.75 0.75 1" />
        <material name="GripperMat" rgba="0.12 0.12 0.12 1" />
        <texture name="sky_tex" type="skybox" builtin="gradient" width="512" height="512" rgb1="0.86 0.90 0.98" rgb2="0.22 0.28 0.36" />
        <texture name="plane_tex" type="2d" builtin="checker" width="256" height="256" rgb1="0.12 0.12 0.12" rgb2="0.84 0.84 0.84" mark="cross" markrgb="0.8 0.8 0.8" />
        <material name="plane_mat" reflectance="0.3" texture="plane_tex" texrepeat="4 4" texuniform="true" />
    </asset>

    <worldbody>
        <geom name="floor" pos="0 0 0" size="0 0 0.25" type="plane" material="plane_mat" contype="0" conaffinity="0" />
        <light directional="true" ambient=".3 .3 .3" pos="30 30 30" dir="0 -.5 -1" diffuse=".5 .5 .5" specular=".5 .5 .5" />
        <light directional="false" pos="-0.5 0.5 1.5" dir="0 -1 0" diffuse=".3 .3 .3" specular=".2 .2 .2" />

        <body pos="-0.16 0.90 0.02" euler="4.71238898 0 3.14159265">
            <body euler="0 -0.82 0">
                <camera name="workbench_camera" euler="0.25 0 0" fovy="43" />
            </body>
        </body>
        <body pos="-1 1.52 0.64" euler="4.71238898 0 3.14159265">
            <body euler="-0.23 0 0">
                <camera name="upper_camera" euler="0 0.09 0" fovy="41" />
            </body>
        </body>

        <body name="base_link" pos="-0.80 0.28 0.00" quat="1 0 0 0">
            <geom name="base_link_visual" type="mesh" mesh="base_link_mesh" material="ArmMat" />

            <body name="link1" pos="0 0 0.166" quat="0.7071054825 0 0 0.7071080799">
                <joint name="joint1" type="hinge" axis="0 0 1" />
                <inertial pos="0.0001590154 -0.0243405579 -0.0177069078" quat="1 0 0 0" mass="0.0608469523" diaginertia="3.70074391646e-05 2.56788832155e-05 3.87763473471e-05" />
                <geom name="link1_visual" type="mesh" mesh="link1_mesh" material="ArmMat" />

                <body name="link2" pos="0 0 0" quat="0.4999981634 0.5 -0.5 0.5000018366">
                    <joint name="joint2" type="hinge" axis="0 0 1" range="-1.5708 1.5708" />
                    <inertial pos="0.100016792 0.0001070663 -0.0107835163" quat="1 0 0 0" mass="0.4335461018" diaginertia="0.00014043417 0.00105045836 0.00104172635" />
                    <geom name="link2_visual" type="mesh" mesh="link2_mesh" material="ArmMat" />

                    <body name="link3" pos="0.2 0 0" quat="-2.597343e-06 -0.7071054825 -0.7071080799 -2.597353e-06">
                        <joint name="joint3" type="hinge" axis="0 0 1" range="0 3.1416" />
                        <inertial pos="0.0413167216 -0.0479933928 -0.010945175" quat="1 0 0 0" mass="0.1634436796" diaginertia="0.0001321428574 7.61011370623e-05 0.0001335204291" />
                        <geom name="link3_visual" type="mesh" mesh="link3_mesh" material="ArmMat" />

                        <body name="link4" pos="0.047631 -0.1845 0" quat="0.7071054825 -0.7071080799 0 0">
                            <joint name="joint4" type="hinge" axis="0 0 1" />
                            <inertial pos="-2.81608084682e-05 -0.00682767077 0.0299455082" quat="1 0 0 0" mass="0.1784658548" diaginertia="0.0001054207096 0.0001112931921 4.42311174656e-05" />
                            <geom name="link4_visual" type="mesh" mesh="link4_mesh" material="ArmMat" />

                            <body name="link5" pos="0 0 0" quat="0.4999981634 0.5 -0.5 0.5000018366">
                                <joint name="joint5" type="hinge" axis="0 0 1" range="-1.5708 0" />
                                <inertial pos="0.0001564318 -0.0617917966 -0.0100252834" quat="1 0 0 0" mass="0.1579322245" diaginertia="0.0001359336558 5.60082572906e-05 0.0001214567006" />
                                <geom name="link5_visual" type="mesh" mesh="link5_mesh" material="ArmMat" />

                                <body name="ee_link" pos="0 -0.125 0" quat="0.7071054825 0.7071080799 0 0">
                                    <joint name="joint6" type="hinge" axis="0 0 1" />
                                    <inertial pos="0 0 -0.0081069" quat="1 0 0 0" mass="0.0088164" diaginertia="6.5293e-07 6.5293e-07 9.3068e-07" />
                                    <geom name="ee_link_visual" type="mesh" mesh="ee_link_mesh" material="ArmMat" />

                                    <body name="robotiq_mount" pos="0 0.08 0" quat="0.707107 -0.707107 0 0">
                                        <geom name="kinova_robotiq_coupler_mesh" type="mesh" mesh="kinova_robotiq_coupler" pos="0 0 0.0466" material="GripperMat" />
                                        <geom name="robotiq_85_base_link_mesh" type="mesh" mesh="robotiq_85_base_link" pos="0 0 0.0016" quat="0.707107 0 -0.707107 0" material="GripperMat" />

                                        <body name="right_driver" pos="0 -0.0306011 0.054904" quat="0.707107 0 -0.707107 0">
                                            <geom name="right_driver_mesh" type="mesh" mesh="robotiq_85_knuckle_link" material="GripperMat" />
                                            <joint name="joint7_1" axis="0 0 1" type="hinge" range="0 0.872664626" />
                                            <body name="right_coupler" pos="0 -0.0315 0">
                                                <geom name="right_coupler_mesh" type="mesh" mesh="robotiq_85_finger_link" material="GripperMat" />
                                                <joint name="joint8_1" axis="0 0 1" type="hinge" range="0 2.967059728" />
                                                <body name="right_follower_link" pos="0.0475 -0.006 0">
                                                    <geom name="right_follower_mesh" type="mesh" mesh="robotiq_85_finger_tip_link" pos="0.0025 0.021 0" material="GripperMat" />
                                                    <joint name="joint9_1" axis="0 0 1" type="hinge" range="0 2.967059728" />
                                                </body>
                                            </body>
                                        </body>

                                        <body name="right_spring_link" pos="0.0016 -0.012 0.0614" quat="0.707107 0 -0.707107 0">
                                            <geom name="right_spring_mesh" type="mesh" mesh="robotiq_85_inner_knuckle_link" pos="0 -0.0005 0.0016" material="GripperMat" />
                                            <joint name="joint10_1" axis="0 0 1" type="hinge" range="0 1.0" />
                                        </body>

                                        <body name="left_driver" pos="0 0.0306011 0.054904" quat="0 0.707107 0 0.707107">
                                            <geom name="left_driver_mesh" type="mesh" mesh="robotiq_85_knuckle_link" material="GripperMat" />
                                            <joint name="joint7_2" axis="0 0 1" type="hinge" range="0 0.872664626" />
                                            <body name="left_coupler" pos="0 -0.0315 0">
                                                <geom name="left_coupler_mesh" type="mesh" mesh="robotiq_85_finger_link" material="GripperMat" />
                                                <joint name="joint8_2" axis="0 0 1" type="hinge" range="0 2.967059728" />
                                                <body name="left_follower_link" pos="0.0475 -0.006 0">
                                                    <geom name="left_follower_mesh" type="mesh" mesh="robotiq_85_finger_tip_link" pos="0.0025 0.021 0" material="GripperMat" />
                                                    <joint name="joint9_2" axis="0 0 1" type="hinge" range="0 2.967059728" />
                                                </body>
                                            </body>
                                        </body>

                                        <body name="left_spring_link" pos="0.0016 0.012 0.0614" quat="0 0.707107 0 0.707107">
                                            <geom name="left_spring_mesh" type="mesh" mesh="robotiq_85_inner_knuckle_link" pos="0 0.0005 0.0016" material="GripperMat" />
                                            <joint name="joint10_2" axis="0 0 1" type="hinge" range="0 1.0" />
                                        </body>
                                    </body>
                                </body>
                            </body>
                        </body>
                    </body>
                </body>
            </body>
        </body>

        <body name="target_body_1" pos="0 0 0.025">
            <geom name="target_1" pos="0 0 0" size="0.03" type="sphere" rgba="0.1 1.0 0.2 0.0" contype="0" conaffinity="0" />
            <site name="target_site_1" pos="0 0 0" size="0.03" type="sphere" rgba="0.1 1.0 0.2 0.0" />
            <joint name="free_x_1" pos="0 0 0" type="slide" axis="1 0 0" frictionloss="0" damping="0" />
            <joint name="free_y_1" pos="0 0 0" type="slide" axis="0 1 0" frictionloss="0" damping="0" />
            <joint name="free_z_1" pos="0 0 0" type="slide" axis="0 0 1" frictionloss="0" damping="0" />
            <joint name="free_ball_1" pos="0 0 0" type="ball" frictionloss="0" damping="0" />
        </body>

        <body name="target_body_2" pos="0 0 0.025">
            <geom name="target_2" pos="0 0 0" size="0.025 0.025 0.025" type="box" rgba="0.01568627451 0.262745098 0.6392156863 0" contype="0" conaffinity="0" />
            <site name="target_site_2" pos="0 0 0" size="0.025 0.025 0.025" type="box" rgba="0.01568627451 0.262745098 0.6392156863 0" />
            <joint name="free_x_2" pos="0 0 0" type="slide" axis="1 0 0" frictionloss="0" damping="0" />
            <joint name="free_y_2" pos="0 0 0" type="slide" axis="0 1 0" frictionloss="0" damping="0" />
            <joint name="free_z_2" pos="0 0 0" type="slide" axis="0 0 1" frictionloss="0" damping="0" />
            <joint name="free_ball_2" pos="0 0 0" type="ball" frictionloss="0" damping="0" />
        </body>

        <body name="target_body_3" pos="0 0 0.025">
            <geom name="target_3" pos="0 0 0" size="0.025 0.025 0.025" type="box" rgba="0.08235294118 0.3058823529 0.03529411765 0" contype="0" conaffinity="0" />
            <site name="target_site_3" pos="0 0 0" size="0.025 0.025 0.025" type="box" rgba="0.08235294118 0.3058823529 0.03529411765 0" />
            <joint name="free_x_3" pos="0 0 0" type="slide" axis="1 0 0" frictionloss="0" damping="0" />
            <joint name="free_y_3" pos="0 0 0" type="slide" axis="0 1 0" frictionloss="0" damping="0" />
            <joint name="free_z_3" pos="0 0 0" type="slide" axis="0 0 1" frictionloss="0" damping="0" />
            <joint name="free_ball_3" pos="0 0 0" type="ball" frictionloss="0" damping="0" />
        </body>

        <body name="target_body_4" pos="0 0 0.025">
            <geom name="target_4" pos="0 0 0" size="0.025 0.025 0.025" type="box" rgba="0.4941176471 0.1176470588 0.04705882353 0" contype="0" conaffinity="0" />
            <site name="target_site_4" pos="0 0 0" size="0.025 0.025 0.025" type="box" rgba="0.4941176471 0.1176470588 0.04705882353 0" />
            <joint name="free_x_4" pos="0 0 0" type="slide" axis="1 0 0" frictionloss="0" damping="0" />
            <joint name="free_y_4" pos="0 0 0" type="slide" axis="0 1 0" frictionloss="0" damping="0" />
            <joint name="free_z_4" pos="0 0 0" type="slide" axis="0 0 1" frictionloss="0" damping="0" />
            <joint name="free_ball_4" pos="0 0 0" type="ball" frictionloss="0" damping="0" />
        </body>
    </worldbody>

    <actuator>
        <motor name="gravity_1" joint="free_z_1" gear="1 0 0 0 0 0" />
        <motor name="gravity_2" joint="free_z_2" gear="1 0 0 0 0 0" />
        <motor name="gravity_3" joint="free_z_3" gear="1 0 0 0 0 0" />
        <motor name="gravity_4" joint="free_z_4" gear="1 0 0 0 0 0" />

        <motor name="close_1" joint="joint7_1" gear="0.2 0 0 0 0 0" />
        <motor name="close_2" joint="joint7_2" gear="0.2 0 0 0 0 0" />

        <motor name="joint1_motor" joint="joint1" gear="1.2" />
        <motor name="joint2_motor" joint="joint2" />
        <motor name="joint3_motor" joint="joint3" />
        <motor name="joint4_motor" joint="joint4" />
        <motor name="joint5_motor" joint="joint5" />
        <motor name="joint6_motor" joint="joint6" />
    </actuator>

    <sensor>
        <touch name="touch_target_1" site="target_site_1" />
        <touch name="touch_target_2" site="target_site_2" />
        <touch name="touch_target_3" site="target_site_3" />
        <touch name="touch_target_4" site="target_site_4" />
    </sensor>
</mujoco>
